Workbook

Sheet Dashboard
A1: FINANCIAL DASHBOARD - CUMULATIVE SUMMARY
A3: CURRENT STATUS | F3: YEAR-TO-DATE SUMMARY
A4: Latest Month: | B4: =IFERROR(__xludf.DUMMYFUNCTION("RIGHT(INDEX(SORT(FILTER(INDIRECT(""Banks_Comparison!3:3""),INDIRECT(""Banks_Comparison!3:3"")<>"""")),1,COLUMNS(FILTER(INDIRECT(""Banks_Comparison!3:3""),INDIRECT(""Banks_Comparison!3:3"")<>""""))),8)"),"45962") -> 45962 | F4: Total Received: | H4: =SUM(Banks_Comparison!5:5) -> 28577792
A5: Bank Balance: | B5: {=INDEX(Banks_Comparison!8:8,1,COUNTA(Banks_Comparison!3:3))} -> 2498320.6 | F5: Total Payments: | H5: =SUM(Banks_Comparison!7:7) -> 27400972
A6: Total Outstanding: | B6: {=INDEX(Outstanding_Comparison!15:15,1,COUNTA(Outstanding_Comparison!3:3))} -> 0 | F6: Net Cash Flow: | H6: =H4-H5 -> 1176820
A7: Advance Balance: | B7: {=INDEX(Advances_Comparison!7:7,1,COUNTA(Advances_Comparison!3:3))} -> 0 | F7: Avg Outstanding: | H7: =AVERAGE(Outstanding_Comparison!15:15) -> 0
A8: Suspense Balance: | B8: {=INDEX(Suspense_Comparison!7:7,1,COUNTA(Suspense_Comparison!3:3))} -> 0
A10: KEY PERFORMANCE INDICATORS
A11: Months Tracked | C11: Highest Bank Balance | E11: Lowest Bank Balance | G11: Average Monthly Revenue
A12: =COUNTA(Banks_Comparison!3:3)-1 -> 11 | C12: =MAX(Banks_Comparison!8:8) -> 3850313.6 | E12: =MIN(Banks_Comparison!8:8) -> 1143292.7 | G12: =AVERAGE(Banks_Comparison!5:5) -> 2597981.1
A13: Total Advances Given | C13: Total Advances Settled | E13: Outstanding Growth Rate | G13: Cash Position
A14: =SUM(Advances_Comparison!5:5) -> 6020817.6 | C14: =SUM(Advances_Comparison!6:6) -> 0 | E14: {=IFERROR((INDEX(Outstanding_Comparison!15:15,1,COUNTA(Outstanding_Comparison!3:3))-INDEX(Outstanding_Comparison!15:15,1,2))/INDEX(Outstanding_Comparison!15:15,1,2)*100,0)&"%"} -> 0% | G14: =B5-B6 -> 2498320.6

Sheet Banks_Comparison
A1: BANKS - MONTHLY COMPARISON
A3: Metric | B3: 45658 | C3: 45689 | D3: 45717 | E3: 45748 | F3: 45778 | G3: 45809 | H3: 45839 | I3: 45870 | J3: 45901 | K3: 45931 | L3: 45962
A4: Opening Balance | B4: =IFERROR('Banks_JAN-2025'!B9,0) -> 1355020 | C4: =IFERROR('Banks_FEB-2025'!B9,0) -> 1141022.6 | D4: =IFERROR('Banks_MAR-2025'!B9,0) -> 2258424.8 | E4: =IFERROR('Banks_APR-2025'!B9,0) -> 1719247.4 | F4: =IFERROR('Banks_MAY-2025'!B9,0) -> 1870886.3 | G4: =IFERROR('Banks_JUN-2025'!B9,0) -> 2485212.9 | H4: =IFERROR('Banks_JUL-2025'!B9,0) -> 1925336.9 | I4: =IFERROR('Banks_AUG-2025'!B9,0) -> 2629726.3 | J4: =IFERROR('Banks_SEP-2025'!B9,0) -> 2448776.9 | K4: =IFERROR('Banks_OCT-2025'!B9,0) -> 3838867.4 | L4: =IFERROR('Banks_NOV-2025'!B9,0) -> 2497819.7
A5: Total Received | B5: =IFERROR('Banks_JAN-2025'!C9,0) -> 3674582 | C5: =IFERROR('Banks_FEB-2025'!C9,0) -> 2714430.9 | D5: =IFERROR('Banks_MAR-2025'!C9,0) -> 2578455.9 | E5: =IFERROR('Banks_APR-2025'!C9,0) -> 1997152.5 | F5: =IFERROR('Banks_MAY-2025'!C9,0) -> 2829237.9 | G5: =IFERROR('Banks_JUN-2025'!C9,0) -> 2824082.1 | H5: =IFERROR('Banks_JUL-2025'!C9,0) -> 2202032.4 | I5: =IFERROR('Banks_AUG-2025'!C9,0) -> 3137664.5 | J5: =IFERROR('Banks_SEP-2025'!C9,0) -> 2231502.5 | K5: =IFERROR('Banks_OCT-2025'!C9,0) -> 4388651.4 | L5: =IFERROR('Banks_NOV-2025'!C9,0) -> 0
A6: Bank Charges | B6: =IFERROR('Banks_JAN-2025'!D9,0) -> 2415.86 | C6: =IFERROR('Banks_FEB-2025'!D9,0) -> 3176.7 | D6: =IFERROR('Banks_MAR-2025'!D9,0) -> 2938.5 | E6: =IFERROR('Banks_APR-2025'!D9,0) -> 2944.07 | F6: =IFERROR('Banks_MAY-2025'!D9,0) -> 3564.49 | G6: =IFERROR('Banks_JUN-2025'!D9,0) -> 3758.16 | H6: =IFERROR('Banks_JUL-2025'!D9,0) -> 3200.98 | I6: =IFERROR('Banks_AUG-2025'!D9,0) -> 3646.93 | J6: =IFERROR('Banks_SEP-2025'!D9,0) -> 4046.1 | K6: =IFERROR('Banks_OCT-2025'!D9,0) -> 4329.87 | L6: =IFERROR('Banks_NOV-2025'!D9,0) -> 0
A7: Total Payments | B7: =IFERROR('Banks_JAN-2025'!E9,0) -> 3886163.6 | C7: =IFERROR('Banks_FEB-2025'!E9,0) -> 1593852 | D7: =IFERROR('Banks_MAR-2025'!E9,0) -> 3114694.8 | E7: =IFERROR('Banks_APR-2025'!E9,0) -> 1842569.6 | F7: =IFERROR('Banks_MAY-2025'!E9,0) -> 2211346.8 | G7: =IFERROR('Banks_JUN-2025'!E9,0) -> 3380199.9 | H7: =IFERROR('Banks_JUL-2025'!E9,0) -> 1494442.1 | I7: =IFERROR('Banks_AUG-2025'!E9,0) -> 3314968.4 | J7: =IFERROR('Banks_SEP-2025'!E9,0) -> 837365.86 | K7: =IFERROR('Banks_OCT-2025'!E9,0) -> 5725369.1 | L7: =IFERROR('Banks_NOV-2025'!E9,0) -> 0
A8: Closing Balance | B8: =IFERROR('Banks_JAN-2025'!F17,0) -> 1143292.7 | C8: =IFERROR('Banks_FEB-2025'!F17,0) -> 2260694.9 | D8: =IFERROR('Banks_MAR-2025'!F17,0) -> 1722677.3 | E8: =IFERROR('Banks_APR-2025'!F17,0) -> 1875053.6 | F8: =IFERROR('Banks_MAY-2025'!F17,0) -> 2489314 | G8: =IFERROR('Banks_JUN-2025'!F17,0) -> 1926729.1 | H8: =IFERROR('Banks_JUL-2025'!F17,0) -> 2631118.5 | I8: =IFERROR('Banks_AUG-2025'!F17,0) -> 2450363.6 | J8: =IFERROR('Banks_SEP-2025'!F17,0) -> 3850313.6 | K8: =IFERROR('Banks_OCT-2025'!F17,0) -> 2498320.6 | L8: =IFERROR('Banks_NOV-2025'!F17,0) -> 2498320.6
A9: Net Cash Flow | B9: =B5-B7 -> -211581.6 | C9: =C5-C7 -> 1120578.9 | D9: =D5-D7 -> -536238.85 | E9: =E5-E7 -> 154582.91 | F9: =F5-F7 -> 617891.08 | G9: =G5-G7 -> -556117.74 | H9: =H5-H7 -> 707590.32 | I9: =I5-I7 -> -177303.81 | ... L9: =L5-L7 -> 0
A10: Month-over-Month % | C10: =IFERROR((C8-B8)/B8,0) -> 0.97735447 | D10: =IFERROR((D8-C8)/C8,0) -> -0.23798769 | E10: =IFERROR((E8-D8)/D8,0) -> 0.088453153 | F10: =IFERROR((F8-E8)/E8,0) -> 0.32759623 | G10: =IFERROR((G8-F8)/F8,0) -> -0.22599997 | H10: =IFERROR((H8-G8)/G8,0) -> 0.36558815 | I10: =IFERROR((I8-H8)/H8,0) -> -0.068698874 | J10: =IFERROR((J8-I8)/I8,0) -> 0.57132338 | ... L10: =IFERROR((L8-K8)/K8,0) -> 0

Sheet Advances_Comparison
A1: ADVANCES - MONTHLY COMPARISON
A3: Metric | B3: 45658 | C3: 45689 | D3: 45717 | E3: 45748 | F3: 45778 | G3: 45809 | H3: 45839 | I3: 45870 | J3: 45901 | K3: 45931 | L3: 45962
A4: Opening Balance | B4: =IFERROR('Advances_JAN-2025'!B3,0) -> 163800.84 | C4: =IFERROR('Advances_FEB-2025'!B3,0) -> 479608.52 | D4: =IFERROR('Advances_MAR-2025'!B3,0) -> 489038.28 | E4: =IFERROR('Advances_APR-2025'!B3,0) -> 491564.28 | F4: =IFERROR('Advances_MAY-2025'!B3,0) -> 541048.28 | G4: =IFERROR('Advances_JUN-2025'!B3,0) -> 472788.43 | H4: =IFERROR('Advances_JUL-2025'!B3,0) -> 504240.98 | I4: =IFERROR('Advances_AUG-2025'!B3,0) -> 452575.39 | J4: =IFERROR('Advances_SEP-2025'!B3,0) -> 473840.39 | K4: =IFERROR('Advances_OCT-2025'!B3,0) -> 504511.39 | L4: =IFERROR('Advances_NOV-2025'!B3,0) -> 540959.39
A5: Advances Given | B5: =IFERROR(SUM('Advances_JAN-2025'!E7:E1000),0) -> 629615.36 | C5: =IFERROR(SUM('Advances_FEB-2025'!E7:E1000),0) -> 813275.72 | D5: =IFERROR(SUM('Advances_MAR-2025'!E7:E1000),0) -> 653526.88 | E5: =IFERROR(SUM('Advances_APR-2025'!E7:E1000),0) -> 752494.88 | F5: =IFERROR(SUM('Advances_MAY-2025'!E7:E1000),0) -> 615975.18 | G5: =IFERROR(SUM('Advances_JUN-2025'!E7:E1000),0) -> 678880.28 | H5: =IFERROR(SUM('Advances_JUL-2025'!E7:E1000),0) -> 577549.1 | I5: =IFERROR(SUM('Advances_AUG-2025'!E7:E1000),0) -> 618079.1 | J5: =IFERROR(SUM('Advances_SEP-2025'!E7:E1000),0) -> 681421.1 | K5: =IFERROR(SUM('Advances_OCT-2025'!E7:E1000),0) -> 0 | L5: =IFERROR(SUM('Advances_NOV-2025'!E7:E1000),0) -> 0
A6: Advances Settled | B6: 0 | C6: 0 | D6: 0 | E6: 0 | F6: 0 | G6: 0 | H6: 0 | I6: 0 | J6: 0 | K6: 0 | L6: 0
A7: Closing Balance | B7: =IFERROR('Advances_JAN-2025'!E3,0) -> 479608.52 | C7: =IFERROR('Advances_FEB-2025'!E3,0) -> 489038.28 | D7: =IFERROR('Advances_MAR-2025'!E3,0) -> 491564.28 | E7: =IFERROR('Advances_APR-2025'!E3,0) -> 541048.28 | F7: =IFERROR('Advances_MAY-2025'!E3,0) -> 472788.43 | G7: =IFERROR('Advances_JUN-2025'!E3,0) -> 504240.98 | H7: =IFERROR('Advances_JUL-2025'!E3,0) -> 453575.39 | I7: =IFERROR('Advances_AUG-2025'!E3,0) -> 473840.39 | J7: =IFERROR('Advances_SEP-2025'!E3,0) -> 504511.39 | K7: =IFERROR('Advances_OCT-2025'!E3,0) -> 540959.39 | L7: =IFERROR('Advances_NOV-2025'!E3,0) -> 0
A8: Settlement Rate %
A9: Average Advance

Sheet Suspense_Comparison
A1: SUSPENSE - MONTHLY COMPARISON
A3: Metric | B3: 45658 | C3: 45689 | D3: 45717 | E3: 45748 | F3: 45778 | G3: 45809 | H3: 45839 | I3: 45870 | J3: 45901 | K3: 45931 | L3: 45962
A4: Opening Balance | B4: =IFERROR('Suspense_JAN-2025'!B3,0) -> -7420.48 | C4: =IFERROR('Suspense_FEB-2025'!B3,0) -> -62065.42 | D4: =IFERROR('Suspense_MAR-2025'!B3,0) -> -162101.8 | E4: =IFERROR('Suspense_APR-2025'!B3,0) -> -105635.53 | F4: =IFERROR('Suspense_MAY-2025'!B3,0) -> -109186.92 | G4: =IFERROR('Suspense_JUN-2025'!B3,0) -> -156614.8 | H4: =IFERROR('Suspense_JUL-2025'!B3,0) -> -149060.68 | I4: =IFERROR('Suspense_AUG-2025'!B3,0) -> -289792.79 | J4: =IFERROR('Suspense_SEP-2025'!B3,0) -> -22235.07 | K4: =IFERROR('Suspense_OCT-2025'!B3,0) -> -59758.42 | L4: =IFERROR('Suspense_NOV-2025'!B3,0) -> -186506.88
A5: Total Debits | B5: =IFERROR(SUM('Suspense_JAN-2025'!E7:E1000)-SUM('Suspense_JAN-2025'!F7:F1000),0) -> -44797.78 | C5: =IFERROR(SUM('Suspense_FEB-2025'!E7:E1000)-SUM('Suspense_FEB-2025'!F7:F1000),0) -> -144834.16 | D5: =IFERROR(SUM('Suspense_MAR-2025'!E7:E1000)-SUM('Suspense_MAR-2025'!F7:F1000),0) -> -96035.42 | E5: =IFERROR(SUM('Suspense_APR-2025'!E7:E1000)-SUM('Suspense_APR-2025'!F7:F1000),0) -> -54928.7 | F5: =IFERROR(SUM('Suspense_MAY-2025'!E7:E1000)-SUM('Suspense_MAY-2025'!F7:F1000),0) -> -78715.91 | G5: =IFERROR(SUM('Suspense_JUN-2025'!E7:E1000)-SUM('Suspense_JUN-2025'!F7:F1000),0) -> -32717.68 | H5: =IFERROR(SUM('Suspense_JUL-2025'!E7:E1000)-SUM('Suspense_JUL-2025'!F7:F1000),0) -> -329290.14 | I5: =IFERROR(SUM('Suspense_AUG-2025'!E7:E1000)-SUM('Suspense_AUG-2025'!F7:F1000),0) -> -44470.14 | J5: =IFERROR(SUM('Suspense_SEP-2025'!E7:E1000)-SUM('Suspense_SEP-2025'!F7:F1000),0) -> -42490.78 | K5: =IFERROR(SUM('Suspense_OCT-2025'!E7:E1000)-SUM('Suspense_OCT-2025'!F7:F1000),0) -> -169239.24 | L5: =IFERROR(SUM('Suspense_NOV-2025'!E7:E1000)-SUM('Suspense_NOV-2025'!F7:F1000),0) -> 0
A6: Total Credits | B6: 0 | C6: 0 | D6: 0 | E6: 0 | F6: 0 | G6: 0 | H6: 0 | I6: 0 | J6: 0 | K6: 0 | L6: 0
A7: Closing Balance | B7: =IFERROR('Suspense_JAN-2025'!E3,0) -> -62065.42 | C7: =IFERROR('Suspense_FEB-2025'!E3,0) -> -162101.8 | D7: =IFERROR('Suspense_MAR-2025'!E3,0) -> -113303.06 | E7: =IFERROR('Suspense_APR-2025'!E3,0) -> -72196.34 | F7: =IFERROR('Suspense_MAY-2025'!E3,0) -> -95983.55 | G7: =IFERROR('Suspense_JUN-2025'!E3,0) -> -49985.32 | H7: =IFERROR('Suspense_JUL-2025'!E3,0) -> -181912.71 | I7: =IFERROR('Suspense_AUG-2025'!E3,0) -> -61737.78 | J7: =IFERROR('Suspense_SEP-2025'!E3,0) -> -59758.42 | K7: =IFERROR('Suspense_OCT-2025'!E3,0) -> -186506.88 | L7: =IFERROR('Suspense_NOV-2025'!E3,0) -> 0
A8: Unidentified Items
A9: Resolution Rate %

Sheet Outstanding_Comparison
A1: CUSTOMER OUTSTANDING - MONTHLY COMPARISON
A3: Salesman | B3: Trend | C3: 45658 | D3: 45689 | E3: 45717 | F3: 45748 | G3: 45778 | H3: 45809 | I3: 45839 | J3: 45870 | K3: 45901 | L3: 45931 | M3: 45962
A4: nidheesh | B4: =IFERROR(__xludf.DUMMYFUNCTION("IF(COUNTA(C4:M4)=0,"""",SPARKLINE(C4:M4,{""charttype"",""line"";""linewidth"",2}))"),"") | C4: =IFERROR(SUMIF('Outstanding_JAN-2025'!$D$19:$D$502,$A4,'Outstanding_JAN-2025'!$G$19:$G$502),0) -> 42552.35 | D4: =IFERROR(SUMIF('Outstanding_FEB-2025'!$D$19:$D$502,$A4,'Outstanding_FEB-2025'!$G$19:$G$502),0) -> 45063.62 | E4: =IFERROR(SUMIF('Outstanding_MAR-2025'!$D$19:$D$502,$A4,'Outstanding_MAR-2025'!$G$19:$G$502),0) -> 57982.29 | F4: =IFERROR(SUMIF('Outstanding_APR-2025'!$D$19:$D$502,$A4,'Outstanding_APR-2025'!$G$19:$G$502),0) -> 55220.63 | G4: =IFERROR(SUMIF('Outstanding_MAY-2025'!$D$19:$D$502,$A4,'Outstanding_MAY-2025'!$G$19:$G$502),0) -> 86898.24 | H4: =IFERROR(SUMIF('Outstanding_JUN-2025'!$D$19:$D$502,$A4,'Outstanding_JUN-2025'!$G$19:$G$502),0) -> 74345.29 | I4: =IFERROR(SUMIF('Outstanding_JUL-2025'!$D$19:$D$502,$A4,'Outstanding_JUL-2025'!$G$19:$G$502),0) -> 71919.95 | J4: =IFERROR(SUMIF('Outstanding_AUG-2025'!$D$19:$D$502,$A4,'Outstanding_AUG-2025'!$G$19:$G$502),0) -> 69826.96 | K4: =IFERROR(SUMIF('Outstanding_SEP-2025'!$D$19:$D$502,$A4,'Outstanding_SEP-2025'!$G$19:$G$502),0) -> 72379.87 | L4: =IFERROR(SUMIF('Outstanding_OCT-2025'!$D$19:$D$502,$A4,'Outstanding_OCT-2025'!$G$19:$G$502),0) -> 76836.77 | M4: =IFERROR(SUMIF('Outstanding_NOV-2025'!$D$19:$D$502,$A4,'Outstanding_NOV-2025'!$G$19:$G$502),0) -> 79345.24
A5: jaseel | B5: =IFERROR(__xludf.DUMMYFUNCTION("IF(COUNTA(C5:M5)=0,"""",SPARKLINE(C5:M5,{""charttype"",""line"";""linewidth"",2}))"),"") | C5: =IFERROR(SUMIF('Outstanding_JAN-2025'!$D$19:$D$502,$A5,'Outstanding_JAN-2025'!$G$19:$G$502),0) -> 24265.64 | D5: =IFERROR(SUMIF('Outstanding_FEB-2025'!$D$19:$D$502,$A5,'Outstanding_FEB-2025'!$G$19:$G$502),0) -> 25395.4 | E5: =IFERROR(SUMIF('Outstanding_MAR-2025'!$D$19:$D$502,$A5,'Outstanding_MAR-2025'!$G$19:$G$502),0) -> 23396.73 | F5: =IFERROR(SUMIF('Outstanding_APR-2025'!$D$19:$D$502,$A5,'Outstanding_APR-2025'!$G$19:$G$502),0) -> 23222.49 | G5: =IFERROR(SUMIF('Outstanding_MAY-2025'!$D$19:$D$502,$A5,'Outstanding_MAY-2025'!$G$19:$G$502),0) -> 18197.45 | H5: =IFERROR(SUMIF('Outstanding_JUN-2025'!$D$19:$D$502,$A5,'Outstanding_JUN-2025'!$G$19:$G$502),0) -> 16255.67 | I5: =IFERROR(SUMIF('Outstanding_JUL-2025'!$D$19:$D$502,$A5,'Outstanding_JUL-2025'!$G$19:$G$502),0) -> 23149.21 | J5: =IFERROR(SUMIF('Outstanding_AUG-2025'!$D$19:$D$502,$A5,'Outstanding_AUG-2025'!$G$19:$G$502),0) -> 24260.07 | K5: =IFERROR(SUMIF('Outstanding_SEP-2025'!$D$19:$D$502,$A5,'Outstanding_SEP-2025'!$G$19:$G$502),0) -> 23755.49 | L5: =IFERROR(SUMIF('Outstanding_OCT-2025'!$D$19:$D$502,$A5,'Outstanding_OCT-2025'!$G$19:$G$502),0) -> 20506.08 | M5: =IFERROR(SUMIF('Outstanding_NOV-2025'!$D$19:$D$502,$A5,'Outstanding_NOV-2025'!$G$19:$G$502),0) -> 19951.36
A6: bassam | B6: =IFERROR(__xludf.DUMMYFUNCTION("IF(COUNTA(C6:M6)=0,"""",SPARKLINE(C6:M6,{""charttype"",""line"";""linewidth"",2}))"),"") | C6: =IFERROR(SUMIF('Outstanding_JAN-2025'!$D$19:$D$502,$A6,'Outstanding_JAN-2025'!$G$19:$G$502),0) -> 17887.52 | D6: =IFERROR(SUMIF('Outstanding_FEB-2025'!$D$19:$D$502,$A6,'Outstanding_FEB-2025'!$G$19:$G$502),0) -> 7652.1 | E6: =IFERROR(SUMIF('Outstanding_MAR-2025'!$D$19:$D$502,$A6,'Outstanding_MAR-2025'!$G$19:$G$502),0) -> 15534.5 | F6: =IFERROR(SUMIF('Outstanding_APR-2025'!$D$19:$D$502,$A6,'Outstanding_APR-2025'!$G$19:$G$502),0) -> 14069.24 | G6: =IFERROR(SUMIF('Outstanding_MAY-2025'!$D$19:$D$502,$A6,'Outstanding_MAY-2025'!$G$19:$G$502),0) -> 24512.04 | H6: =IFERROR(SUMIF('Outstanding_JUN-2025'!$D$19:$D$502,$A6,'Outstanding_JUN-2025'!$G$19:$G$502),0) -> 22573.22 | I6: =IFERROR(SUMIF('Outstanding_JUL-2025'!$D$19:$D$502,$A6,'Outstanding_JUL-2025'!$G$19:$G$502),0) -> 25052.83 | J6: =IFERROR(SUMIF('Outstanding_AUG-2025'!$D$19:$D$502,$A6,'Outstanding_AUG-2025'!$G$19:$G$502),0) -> 19724.86 | K6: =IFERROR(SUMIF('Outstanding_SEP-2025'!$D$19:$D$502,$A6,'Outstanding_SEP-2025'!$G$19:$G$502),0) -> 24945 | L6: =IFERROR(SUMIF('Outstanding_OCT-2025'!$D$19:$D$502,$A6,'Outstanding_OCT-2025'!$G$19:$G$502),0) -> 25219.28 | M6: =IFERROR(SUMIF('Outstanding_NOV-2025'!$D$19:$D$502,$A6,'Outstanding_NOV-2025'!$G$19:$G$502),0) -> 22733.87
A7: akmal | B7: =IFERROR(__xludf.DUMMYFUNCTION("IF(COUNTA(C7:M7)=0,"""",SPARKLINE(C7:M7,{""charttype"",""line"";""linewidth"",2}))"),"") | C7: =IFERROR(SUMIF('Outstanding_JAN-2025'!$D$19:$D$502,$A7,'Outstanding_JAN-2025'!$G$19:$G$502),0) -> 575.93 | D7: =IFERROR(SUMIF('Outstanding_FEB-2025'!$D$19:$D$502,$A7,'Outstanding_FEB-2025'!$G$19:$G$502),0) -> 837.92 | E7: =IFERROR(SUMIF('Outstanding_MAR-2025'!$D$19:$D$502,$A7,'Outstanding_MAR-2025'!$G$19:$G$502),0) -> 15595.44 | F7: =IFERROR(SUMIF('Outstanding_APR-2025'!$D$19:$D$502,$A7,'Outstanding_APR-2025'!$G$19:$G$502),0) -> 14302.95 | G7: =IFERROR(SUMIF('Outstanding_MAY-2025'!$D$19:$D$502,$A7,'Outstanding_MAY-2025'!$G$19:$G$502),0) -> 17759.41 | H7: =IFERROR(SUMIF('Outstanding_JUN-2025'!$D$19:$D$502,$A7,'Outstanding_JUN-2025'!$G$19:$G$502),0) -> 21216.07 | I7: =IFERROR(SUMIF('Outstanding_JUL-2025'!$D$19:$D$502,$A7,'Outstanding_JUL-2025'!$G$19:$G$502),0) -> 32516.24 | J7: =IFERROR(SUMIF('Outstanding_AUG-2025'!$D$19:$D$502,$A7,'Outstanding_AUG-2025'!$G$19:$G$502),0) -> 38060.96 | K7: =IFERROR(SUMIF('Outstanding_SEP-2025'!$D$19:$D$502,$A7,'Outstanding_SEP-2025'!$G$19:$G$502),0) -> 54291.15 | L7: =IFERROR(SUMIF('Outstanding_OCT-2025'!$D$19:$D$502,$A7,'Outstanding_OCT-2025'!$G$19:$G$502),0) -> 45795.01 | M7: =IFERROR(SUMIF('Outstanding_NOV-2025'!$D$19:$D$502,$A7,'Outstanding_NOV-2025'!$G$19:$G$502),0) -> 34121.05
A8: arshad | B8: =IFERROR(__xludf.DUMMYFUNCTION("IF(COUNTA(C8:M8)=0,"""",SPARKLINE(C8:M8,{""charttype"",""line"";""linewidth"",2}))"),"") | C8: =IFERROR(SUMIF('Outstanding_JAN-2025'!$D$19:$D$502,$A8,'Outstanding_JAN-2025'!$G$19:$G$502),0) -> 401746.31 | D8: =IFERROR(SUMIF('Outstanding_FEB-2025'!$D$19:$D$502,$A8,'Outstanding_FEB-2025'!$G$19:$G$502),0) -> 386314.4 | E8: =IFERROR(SUMIF('Outstanding_MAR-2025'!$D$19:$D$502,$A8,'Outstanding_MAR-2025'!$G$19:$G$502),0) -> 408441.36 | F8: =IFERROR(SUMIF('Outstanding_APR-2025'!$D$19:$D$502,$A8,'Outstanding_APR-2025'!$G$19:$G$502),0) -> 390433.84 | G8: =IFERROR(SUMIF('Outstanding_MAY-2025'!$D$19:$D$502,$A8,'Outstanding_MAY-2025'!$G$19:$G$502),0) -> 372922.38 | H8: =IFERROR(SUMIF('Outstanding_JUN-2025'!$D$19:$D$502,$A8,'Outstanding_JUN-2025'!$G$19:$G$502),0) -> 396181.7 | I8: =IFERROR(SUMIF('Outstanding_JUL-2025'!$D$19:$D$502,$A8,'Outstanding_JUL-2025'!$G$19:$G$502),0) -> 398562.17 | J8: =IFERROR(SUMIF('Outstanding_AUG-2025'!$D$19:$D$502,$A8,'Outstanding_AUG-2025'!$G$19:$G$502),0) -> 329881.32 | K8: =IFERROR(SUMIF('Outstanding_SEP-2025'!$D$19:$D$502,$A8,'Outstanding_SEP-2025'!$G$19:$G$502),0) -> 343351.34 | L8: =IFERROR(SUMIF('Outstanding_OCT-2025'!$D$19:$D$502,$A8,'Outstanding_OCT-2025'!$G$19:$G$502),0) -> 366543.83 | M8: =IFERROR(SUMIF('Outstanding_NOV-2025'!$D$19:$D$502,$A8,'Outstanding_NOV-2025'!$G$19:$G$502),0) -> 486637.4
A9: Shameer riyadh | B9: =IFERROR(__xludf.DUMMYFUNCTION("IF(COUNTA(C9:M9)=0,"""",SPARKLINE(C9:M9,{""charttype"",""line"";""linewidth"",2}))"),"") | C9: =IFERROR(SUMIF('Outstanding_JAN-2025'!$D$19:$D$502,$A9,'Outstanding_JAN-2025'!$G$19:$G$502),0) -> 22083.16 | D9: =IFERROR(SUMIF('Outstanding_FEB-2025'!$D$19:$D$502,$A9,'Outstanding_FEB-2025'!$G$19:$G$502),0) -> 45700.21 | E9: =IFERROR(SUMIF('Outstanding_MAR-2025'!$D$19:$D$502,$A9,'Outstanding_MAR-2025'!$G$19:$G$502),0) -> 45671.06 | F9: =IFERROR(SUMIF('Outstanding_APR-2025'!$D$19:$D$502,$A9,'Outstanding_APR-2025'!$G$19:$G$502),0) -> 59897.57 | G9: =IFERROR(SUMIF('Outstanding_MAY-2025'!$D$19:$D$502,$A9,'Outstanding_MAY-2025'!$G$19:$G$502),0) -> 65021.92 | H9: =IFERROR(SUMIF('Outstanding_JUN-2025'!$D$19:$D$502,$A9,'Outstanding_JUN-2025'!$G$19:$G$502),0) -> 69892.24 | I9: =IFERROR(SUMIF('Outstanding_JUL-2025'!$D$19:$D$502,$A9,'Outstanding_JUL-2025'!$G$19:$G$502),0) -> 66813.14 | J9: =IFERROR(SUMIF('Outstanding_AUG-2025'!$D$19:$D$502,$A9,'Outstanding_AUG-2025'!$G$19:$G$502),0) -> 71998.44 | K9: =IFERROR(SUMIF('Outstanding_SEP-2025'!$D$19:$D$502,$A9,'Outstanding_SEP-2025'!$G$19:$G$502),0) -> 77103.34 | L9: =IFERROR(SUMIF('Outstanding_OCT-2025'!$D$19:$D$502,$A9,'Outstanding_OCT-2025'!$G$19:$G$502),0) -> 72659.84 | M9: =IFERROR(SUMIF('Outstanding_NOV-2025'!$D$19:$D$502,$A9,'Outstanding_NOV-2025'!$G$19:$G$502),0) -> 92907.92
A10: company sales | B10: =IFERROR(__xludf.DUMMYFUNCTION("IF(COUNTA(C10:M10)=0,"""",SPARKLINE(C10:M10,{""charttype"",""line"";""linewidth"",2}))"),"") | C10: =IFERROR(SUMIF('Outstanding_JAN-2025'!$D$19:$D$502,$A10,'Outstanding_JAN-2025'!$G$19:$G$502),0) -> 985953.74 | D10: =IFERROR(SUMIF('Outstanding_FEB-2025'!$D$19:$D$502,$A10,'Outstanding_FEB-2025'!$G$19:$G$502),0) -> 778183.07 | E10: =IFERROR(SUMIF('Outstanding_MAR-2025'!$D$19:$D$502,$A10,'Outstanding_MAR-2025'!$G$19:$G$502),0) -> 650384.77 | F10: =IFERROR(SUMIF('Outstanding_APR-2025'!$D$19:$D$502,$A10,'Outstanding_APR-2025'!$G$19:$G$502),0) -> 809040.72 | G10: =IFERROR(SUMIF('Outstanding_MAY-2025'!$D$19:$D$502,$A10,'Outstanding_MAY-2025'!$G$19:$G$502),0) -> 1349535.5 | H10: =IFERROR(SUMIF('Outstanding_JUN-2025'!$D$19:$D$502,$A10,'Outstanding_JUN-2025'!$G$19:$G$502),0) -> 1250206 | I10: =IFERROR(SUMIF('Outstanding_JUL-2025'!$D$19:$D$502,$A10,'Outstanding_JUL-2025'!$G$19:$G$502),0) -> 1434277.6 | J10: =IFERROR(SUMIF('Outstanding_AUG-2025'!$D$19:$D$502,$A10,'Outstanding_AUG-2025'!$G$19:$G$502),0) -> 1087241.2 | K10: =IFERROR(SUMIF('Outstanding_SEP-2025'!$D$19:$D$502,$A10,'Outstanding_SEP-2025'!$G$19:$G$502),0) -> 1068473.3 | L10: =IFERROR(SUMIF('Outstanding_OCT-2025'!$D$19:$D$502,$A10,'Outstanding_OCT-2025'!$G$19:$G$502),0) -> 1056569.4 | M10: =IFERROR(SUMIF('Outstanding_NOV-2025'!$D$19:$D$502,$A10,'Outstanding_NOV-2025'!$G$19:$G$502),0) -> 976412.87
A11: shafi | B11: =IFERROR(__xludf.DUMMYFUNCTION("IF(COUNTA(C11:M11)=0,"""",SPARKLINE(C11:M11,{""charttype"",""line"";""linewidth"",2}))"),"") | C11: =IFERROR(SUMIF('Outstanding_JAN-2025'!$D$19:$D$502,$A11,'Outstanding_JAN-2025'!$G$19:$G$502),0) -> 0 | D11: =IFERROR(SUMIF('Outstanding_FEB-2025'!$D$19:$D$502,$A11,'Outstanding_FEB-2025'!$G$19:$G$502),0) -> 0 | E11: =IFERROR(SUMIF('Outstanding_MAR-2025'!$D$19:$D$502,$A11,'Outstanding_MAR-2025'!$G$19:$G$502),0) -> 779.99 | F11: =IFERROR(SUMIF('Outstanding_APR-2025'!$D$19:$D$502,$A11,'Outstanding_APR-2025'!$G$19:$G$502),0) -> 4846.35 | G11: =IFERROR(SUMIF('Outstanding_MAY-2025'!$D$19:$D$502,$A11,'Outstanding_MAY-2025'!$G$19:$G$502),0) -> 8545.51 | H11: =IFERROR(SUMIF('Outstanding_JUN-2025'!$D$19:$D$502,$A11,'Outstanding_JUN-2025'!$G$19:$G$502),0) -> 7230.55 | I11: =IFERROR(SUMIF('Outstanding_JUL-2025'!$D$19:$D$502,$A11,'Outstanding_JUL-2025'!$G$19:$G$502),0) -> 13792.6 | J11: =IFERROR(SUMIF('Outstanding_AUG-2025'!$D$19:$D$502,$A11,'Outstanding_AUG-2025'!$G$19:$G$502),0) -> 16057.58 | K11: =IFERROR(SUMIF('Outstanding_SEP-2025'!$D$19:$D$502,$A11,'Outstanding_SEP-2025'!$G$19:$G$502),0) -> 17862.18 | L11: =IFERROR(SUMIF('Outstanding_OCT-2025'!$D$19:$D$502,$A11,'Outstanding_OCT-2025'!$G$19:$G$502),0) -> 17259.59 | M11: =IFERROR(SUMIF('Outstanding_NOV-2025'!$D$19:$D$502,$A11,'Outstanding_NOV-2025'!$G$19:$G$502),0) -> 18398.82
A12: ashik | B12: =IFERROR(__xludf.DUMMYFUNCTION("IF(COUNTA(C12:M12)=0,"""",SPARKLINE(C12:M12,{""charttype"",""line"";""linewidth"",2}))"),"") | C12: =IFERROR(SUMIF('Outstanding_JAN-2025'!$D$19:$D$502,$A12,'Outstanding_JAN-2025'!$G$19:$G$502),0) -> 3674.58 | D12: =IFERROR(SUMIF('Outstanding_FEB-2025'!$D$19:$D$502,$A12,'Outstanding_FEB-2025'!$G$19:$G$502),0) -> 3500.62 | E12: =IFERROR(SUMIF('Outstanding_MAR-2025'!$D$19:$D$502,$A12,'Outstanding_MAR-2025'!$G$19:$G$502),0) -> 3408.64 | F12: =IFERROR(SUMIF('Outstanding_APR-2025'!$D$19:$D$502,$A12,'Outstanding_APR-2025'!$G$19:$G$502),0) -> 4062.21 | G12: =IFERROR(SUMIF('Outstanding_MAY-2025'!$D$19:$D$502,$A12,'Outstanding_MAY-2025'!$G$19:$G$502),0) -> 15556.35 | H12: =IFERROR(SUMIF('Outstanding_JUN-2025'!$D$19:$D$502,$A12,'Outstanding_JUN-2025'!$G$19:$G$502),0) -> 13950.79 | I12: =IFERROR(SUMIF('Outstanding_JUL-2025'!$D$19:$D$502,$A12,'Outstanding_JUL-2025'!$G$19:$G$502),0) -> 16876.6 | J12: =IFERROR(SUMIF('Outstanding_AUG-2025'!$D$19:$D$502,$A12,'Outstanding_AUG-2025'!$G$19:$G$502),0) -> 14387.17 | K12: =IFERROR(SUMIF('Outstanding_SEP-2025'!$D$19:$D$502,$A12,'Outstanding_SEP-2025'!$G$19:$G$502),0) -> 15423.13 | L12: =IFERROR(SUMIF('Outstanding_OCT-2025'!$D$19:$D$502,$A12,'Outstanding_OCT-2025'!$G$19:$G$502),0) -> 27926.05 | M12: =IFERROR(SUMIF('Outstanding_NOV-2025'!$D$19:$D$502,$A12,'Outstanding_NOV-2025'!$G$19:$G$502),0) -> 17807.28
A13: dhiya | B13: =IFERROR(__xludf.DUMMYFUNCTION("IF(COUNTA(C13:M13)=0,"""",SPARKLINE(C13:M13,{""charttype"",""line"";""linewidth"",2}))"),"") | C13: =IFERROR(SUMIF('Outstanding_JAN-2025'!$D$19:$D$502,$A13,'Outstanding_JAN-2025'!$G$19:$G$502),0) -> 237083.08 | D13: =IFERROR(SUMIF('Outstanding_FEB-2025'!$D$19:$D$502,$A13,'Outstanding_FEB-2025'!$G$19:$G$502),0) -> 228497.88 | E13: =IFERROR(SUMIF('Outstanding_MAR-2025'!$D$19:$D$502,$A13,'Outstanding_MAR-2025'!$G$19:$G$502),0) -> 231169.37 | F13: =IFERROR(SUMIF('Outstanding_APR-2025'!$D$19:$D$502,$A13,'Outstanding_APR-2025'!$G$19:$G$502),0) -> 264736.23 | G13: =IFERROR(SUMIF('Outstanding_MAY-2025'!$D$19:$D$502,$A13,'Outstanding_MAY-2025'!$G$19:$G$502),0) -> 248652.07 | H13: =IFERROR(SUMIF('Outstanding_JUN-2025'!$D$19:$D$502,$A13,'Outstanding_JUN-2025'!$G$19:$G$502),0) -> 229073.43 | I13: =IFERROR(SUMIF('Outstanding_JUL-2025'!$D$19:$D$502,$A13,'Outstanding_JUL-2025'!$G$19:$G$502),0) -> 214810.77 | J13: =IFERROR(SUMIF('Outstanding_AUG-2025'!$D$19:$D$502,$A13,'Outstanding_AUG-2025'!$G$19:$G$502),0) -> 250098.41 | K13: =IFERROR(SUMIF('Outstanding_SEP-2025'!$D$19:$D$502,$A13,'Outstanding_SEP-2025'!$G$19:$G$502),0) -> 235777.05 | L13: =IFERROR(SUMIF('Outstanding_OCT-2025'!$D$19:$D$502,$A13,'Outstanding_OCT-2025'!$G$19:$G$502),0) -> 245613.5 | M13: =IFERROR(SUMIF('Outstanding_NOV-2025'!$D$19:$D$502,$A13,'Outstanding_NOV-2025'!$G$19:$G$502),0) -> 270754.61
A14: khalid | B14: =IFERROR(__xludf.DUMMYFUNCTION("IF(COUNTA(C14:M14)=0,"""",SPARKLINE(C14:M14,{""charttype"",""line"";""linewidth"",2}))"),"") | C14: =IFERROR(SUMIF('Outstanding_JAN-2025'!$D$19:$D$502,$A14,'Outstanding_JAN-2025'!$G$19:$G$502),0) -> 55184.18 | D14: =IFERROR(SUMIF('Outstanding_FEB-2025'!$D$19:$D$502,$A14,'Outstanding_FEB-2025'!$G$19:$G$502),0) -> 57646.36 | E14: =IFERROR(SUMIF('Outstanding_MAR-2025'!$D$19:$D$502,$A14,'Outstanding_MAR-2025'!$G$19:$G$502),0) -> 49421.1 | F14: =IFERROR(SUMIF('Outstanding_APR-2025'!$D$19:$D$502,$A14,'Outstanding_APR-2025'!$G$19:$G$502),0) -> 65418.65 | G14: =IFERROR(SUMIF('Outstanding_MAY-2025'!$D$19:$D$502,$A14,'Outstanding_MAY-2025'!$G$19:$G$502),0) -> 72741.9 | H14: =IFERROR(SUMIF('Outstanding_JUN-2025'!$D$19:$D$502,$A14,'Outstanding_JUN-2025'!$G$19:$G$502),0) -> 81121.23 | I14: =IFERROR(SUMIF('Outstanding_JUL-2025'!$D$19:$D$502,$A14,'Outstanding_JUL-2025'!$G$19:$G$502),0) -> 88733.24 | J14: =IFERROR(SUMIF('Outstanding_AUG-2025'!$D$19:$D$502,$A14,'Outstanding_AUG-2025'!$G$19:$G$502),0) -> 88782.28 | K14: =IFERROR(SUMIF('Outstanding_SEP-2025'!$D$19:$D$502,$A14,'Outstanding_SEP-2025'!$G$19:$G$502),0) -> 85162.44 | L14: =IFERROR(SUMIF('Outstanding_OCT-2025'!$D$19:$D$502,$A14,'Outstanding_OCT-2025'!$G$19:$G$502),0) -> 99007.14 | M14: =IFERROR(SUMIF('Outstanding_NOV-2025'!$D$19:$D$502,$A14,'Outstanding_NOV-2025'!$G$19:$G$502),0) -> 89837.02
A15: shabeer | B15: =IFERROR(__xludf.DUMMYFUNCTION("IF(COUNTA(C15:M15)=0,"""",SPARKLINE(C15:M15,{""charttype"",""line"";""linewidth"",2}))"),"") | C15: =IFERROR(SUMIF('Outstanding_JAN-2025'!$D$19:$D$502,$A15,'Outstanding_JAN-2025'!$G$19:$G$502),0) -> 0 | D15: =IFERROR(SUMIF('Outstanding_FEB-2025'!$D$19:$D$502,$A15,'Outstanding_FEB-2025'!$G$19:$G$502),0) -> 0 | E15: =IFERROR(SUMIF('Outstanding_MAR-2025'!$D$19:$D$502,$A15,'Outstanding_MAR-2025'!$G$19:$G$502),0) -> 0 | F15: =IFERROR(SUMIF('Outstanding_APR-2025'!$D$19:$D$502,$A15,'Outstanding_APR-2025'!$G$19:$G$502),0) -> 0 | G15: =IFERROR(SUMIF('Outstanding_MAY-2025'!$D$19:$D$502,$A15,'Outstanding_MAY-2025'!$G$19:$G$502),0) -> 0 | H15: =IFERROR(SUMIF('Outstanding_JUN-2025'!$D$19:$D$502,$A15,'Outstanding_JUN-2025'!$G$19:$G$502),0) -> 0 | I15: =IFERROR(SUMIF('Outstanding_JUL-2025'!$D$19:$D$502,$A15,'Outstanding_JUL-2025'!$G$19:$G$502),0) -> 0 | J15: =IFERROR(SUMIF('Outstanding_AUG-2025'!$D$19:$D$502,$A15,'Outstanding_AUG-2025'!$G$19:$G$502),0) -> 0 | K15: =IFERROR(SUMIF('Outstanding_SEP-2025'!$D$19:$D$502,$A15,'Outstanding_SEP-2025'!$G$19:$G$502),0) -> 0 | L15: =IFERROR(SUMIF('Outstanding_OCT-2025'!$D$19:$D$502,$A15,'Outstanding_OCT-2025'!$G$19:$G$502),0) -> 0 | M15: =IFERROR(SUMIF('Outstanding_NOV-2025'!$D$19:$D$502,$A15,'Outstanding_NOV-2025'!$G$19:$G$502),0) -> 0
A16: al ahsa-4 | B16: =IFERROR(__xludf.DUMMYFUNCTION("IF(COUNTA(C16:M16)=0,"""",SPARKLINE(C16:M16,{""charttype"",""line"";""linewidth"",2}))"),"") | C16: =IFERROR(SUMIF('Outstanding_JAN-2025'!$D$19:$D$502,$A16,'Outstanding_JAN-2025'!$G$19:$G$502),0) -> 0 | D16: =IFERROR(SUMIF('Outstanding_FEB-2025'!$D$19:$D$502,$A16,'Outstanding_FEB-2025'!$G$19:$G$502),0) -> 0 | E16: =IFERROR(SUMIF('Outstanding_MAR-2025'!$D$19:$D$502,$A16,'Outstanding_MAR-2025'!$G$19:$G$502),0) -> 0 | F16: =IFERROR(SUMIF('Outstanding_APR-2025'!$D$19:$D$502,$A16,'Outstanding_APR-2025'!$G$19:$G$502),0) -> 0 | G16: =IFERROR(SUMIF('Outstanding_MAY-2025'!$D$19:$D$502,$A16,'Outstanding_MAY-2025'!$G$19:$G$502),0) -> 0 | H16: =IFERROR(SUMIF('Outstanding_JUN-2025'!$D$19:$D$502,$A16,'Outstanding_JUN-2025'!$G$19:$G$502),0) -> 0 | I16: =IFERROR(SUMIF('Outstanding_JUL-2025'!$D$19:$D$502,$A16,'Outstanding_JUL-2025'!$G$19:$G$502),0) -> 0 | J16: =IFERROR(SUMIF('Outstanding_AUG-2025'!$D$19:$D$502,$A16,'Outstanding_AUG-2025'!$G$19:$G$502),0) -> 0 | K16: =IFERROR(SUMIF('Outstanding_SEP-2025'!$D$19:$D$502,$A16,'Outstanding_SEP-2025'!$G$19:$G$502),0) -> 0 | L16: =IFERROR(SUMIF('Outstanding_OCT-2025'!$D$19:$D$502,$A16,'Outstanding_OCT-2025'!$G$19:$G$502),0) -> 0 | M16: =IFERROR(SUMIF('Outstanding_NOV-2025'!$D$19:$D$502,$A16,'Outstanding_NOV-2025'!$G$19:$G$502),0) -> 20589.67
A17: samir dmm | B17: =IFERROR(__xludf.DUMMYFUNCTION("IF(COUNTA(C17:M17)=0,"""",SPARKLINE(C17:M17,{""charttype"",""line"";""linewidth"",2}))"),"") | C17: =IFERROR(SUMIF('Outstanding_JAN-2025'!$D$19:$D$502,$A17,'Outstanding_JAN-2025'!$G$19:$G$502),0) -> 0 | D17: =IFERROR(SUMIF('Outstanding_FEB-2025'!$D$19:$D$502,$A17,'Outstanding_FEB-2025'!$G$19:$G$502),0) -> 0 | E17: =IFERROR(SUMIF('Outstanding_MAR-2025'!$D$19:$D$502,$A17,'Outstanding_MAR-2025'!$G$19:$G$502),0) -> 0 | F17: =IFERROR(SUMIF('Outstanding_APR-2025'!$D$19:$D$502,$A17,'Outstanding_APR-2025'!$G$19:$G$502),0) -> 0 | G17: =IFERROR(SUMIF('Outstanding_MAY-2025'!$D$19:$D$502,$A17,'Outstanding_MAY-2025'!$G$19:$G$502),0) -> 0 | H17: =IFERROR(SUMIF('Outstanding_JUN-2025'!$D$19:$D$502,$A17,'Outstanding_JUN-2025'!$G$19:$G$502),0) -> 0 | I17: =IFERROR(SUMIF('Outstanding_JUL-2025'!$D$19:$D$502,$A17,'Outstanding_JUL-2025'!$G$19:$G$502),0) -> 0 | J17: =IFERROR(SUMIF('Outstanding_AUG-2025'!$D$19:$D$502,$A17,'Outstanding_AUG-2025'!$G$19:$G$502),0) -> 0 | K17: =IFERROR(SUMIF('Outstanding_SEP-2025'!$D$19:$D$502,$A17,'Outstanding_SEP-2025'!$G$19:$G$502),0) -> 0 | L17: =IFERROR(SUMIF('Outstanding_OCT-2025'!$D$19:$D$502,$A17,'Outstanding_OCT-2025'!$G$19:$G$502),0) -> 0 | M17: =IFERROR(SUMIF('Outstanding_NOV-2025'!$D$19:$D$502,$A17,'Outstanding_NOV-2025'!$G$19:$G$502),0) -> 30912.4
A18: shareef | B18: =IFERROR(__xludf.DUMMYFUNCTION("IF(COUNTA(C18:M18)=0,"""",SPARKLINE(C18:M18,{""charttype"",""line"";""linewidth"",2}))"),"") | C18: =IFERROR(SUMIF('Outstanding_JAN-2025'!$D$19:$D$502,$A18,'Outstanding_JAN-2025'!$G$19:$G$502),0) -> 0 | D18: =IFERROR(SUMIF('Outstanding_FEB-2025'!$D$19:$D$502,$A18,'Outstanding_FEB-2025'!$G$19:$G$502),0) -> 0 | E18: =IFERROR(SUMIF('Outstanding_MAR-2025'!$D$19:$D$502,$A18,'Outstanding_MAR-2025'!$G$19:$G$502),0) -> 0 | F18: =IFERROR(SUMIF('Outstanding_APR-2025'!$D$19:$D$502,$A18,'Outstanding_APR-2025'!$G$19:$G$502),0) -> 4990.26 | G18: =IFERROR(SUMIF('Outstanding_MAY-2025'!$D$19:$D$502,$A18,'Outstanding_MAY-2025'!$G$19:$G$502),0) -> 4366.48 | H18: =IFERROR(SUMIF('Outstanding_JUN-2025'!$D$19:$D$502,$A18,'Outstanding_JUN-2025'!$G$19:$G$502),0) -> 4366.48 | I18: =IFERROR(SUMIF('Outstanding_JUL-2025'!$D$19:$D$502,$A18,'Outstanding_JUL-2025'!$G$19:$G$502),0) -> 4366.48 | J18: =IFERROR(SUMIF('Outstanding_AUG-2025'!$D$19:$D$502,$A18,'Outstanding_AUG-2025'!$G$19:$G$502),0) -> 4257.5 | K18: =IFERROR(SUMIF('Outstanding_SEP-2025'!$D$19:$D$502,$A18,'Outstanding_SEP-2025'!$G$19:$G$502),0) -> 0 | L18: =IFERROR(SUMIF('Outstanding_OCT-2025'!$D$19:$D$502,$A18,'Outstanding_OCT-2025'!$G$19:$G$502),0) -> 0 | M18: =IFERROR(SUMIF('Outstanding_NOV-2025'!$D$19:$D$502,$A18,'Outstanding_NOV-2025'!$G$19:$G$502),0) -> 4257.5
A19: samir | B19: =IFERROR(__xludf.DUMMYFUNCTION("IF(COUNTA(C19:M19)=0,"""",SPARKLINE(C19:M19,{""charttype"",""line"";""linewidth"",2}))"),"") | C19: =IFERROR(SUMIF('Outstanding_JAN-2025'!$D$19:$D$502,$A19,'Outstanding_JAN-2025'!$G$19:$G$502),0) -> 4863 | D19: =IFERROR(SUMIF('Outstanding_FEB-2025'!$D$19:$D$502,$A19,'Outstanding_FEB-2025'!$G$19:$G$502),0) -> 11134.02 | E19: =IFERROR(SUMIF('Outstanding_MAR-2025'!$D$19:$D$502,$A19,'Outstanding_MAR-2025'!$G$19:$G$502),0) -> 6051.96 | F19: =IFERROR(SUMIF('Outstanding_APR-2025'!$D$19:$D$502,$A19,'Outstanding_APR-2025'!$G$19:$G$502),0) -> 5859.02 | G19: =IFERROR(SUMIF('Outstanding_MAY-2025'!$D$19:$D$502,$A19,'Outstanding_MAY-2025'!$G$19:$G$502),0) -> 3245 | H19: =IFERROR(SUMIF('Outstanding_JUN-2025'!$D$19:$D$502,$A19,'Outstanding_JUN-2025'!$G$19:$G$502),0) -> 3046 | I19: =IFERROR(SUMIF('Outstanding_JUL-2025'!$D$19:$D$502,$A19,'Outstanding_JUL-2025'!$G$19:$G$502),0) -> 8916.95 | J19: =IFERROR(SUMIF('Outstanding_AUG-2025'!$D$19:$D$502,$A19,'Outstanding_AUG-2025'!$G$19:$G$502),0) -> 12195.64 | K19: =IFERROR(SUMIF('Outstanding_SEP-2025'!$D$19:$D$502,$A19,'Outstanding_SEP-2025'!$G$19:$G$502),0) -> 5260 | L19: =IFERROR(SUMIF('Outstanding_OCT-2025'!$D$19:$D$502,$A19,'Outstanding_OCT-2025'!$G$19:$G$502),0) -> 9086.56 | M19: =IFERROR(SUMIF('Outstanding_NOV-2025'!$D$19:$D$502,$A19,'Outstanding_NOV-2025'!$G$19:$G$502),0) -> 15016.49
A20: TOTAL | B20: =IFERROR(__xludf.DUMMYFUNCTION("IF(COUNTA(C20:M20)=0,"""",SPARKLINE(C20:M20,{""charttype"",""line"";""linewidth"",2}))"),"") | C20: =SUM(C4:C19) -> 1795869.5 | D20: =SUM(D4:D19) -> 1589925.6 | E20: =SUM(E4:E19) -> 1507837.2 | F20: =SUM(F4:F19) -> 1716100.2 | G20: =SUM(G4:G19) -> 2287954.2 | H20: =SUM(H4:H19) -> 2189458.7 | I20: =SUM(I4:I19) -> 2399787.8 | J20: =SUM(J4:J19) -> 2026772.4 | ... M20: =SUM(M4:M19) -> 2179683.5
A21: MoM Δ (TOTAL) | D21: =IF(C20="","",IFERROR(IF(D20=C20,"—",IF(D20>C20,"▲ +"&TEXT((D20-C20)/C20,"0.0%"),"▼ -"&TEXT(ABS((D20-C20)/C20),"0.0%"))),"")) -> ▼ -11.5% | E21: =IF(D20="","",IFERROR(IF(E20=D20,"—",IF(E20>D20,"▲ +"&TEXT((E20-D20)/D20,"0.0%"),"▼ -"&TEXT(ABS((E20-D20)/D20),"0.0%"))),"")) -> ▼ -5.2% | F21: =IF(E20="","",IFERROR(IF(F20=E20,"—",IF(F20>E20,"▲ +"&TEXT((F20-E20)/E20,"0.0%"),"▼ -"&TEXT(ABS((F20-E20)/E20),"0.0%"))),"")) -> ▲ +13.8% | G21: =IF(F20="","",IFERROR(IF(G20=F20,"—",IF(G20>F20,"▲ +"&TEXT((G20-F20)/F20,"0.0%"),"▼ -"&TEXT(ABS((G20-F20)/F20),"0.0%"))),"")) -> ▲ +33.3% | H21: =IF(G20="","",IFERROR(IF(H20=G20,"—",IF(H20>G20,"▲ +"&TEXT((H20-G20)/G20,"0.0%"),"▼ -"&TEXT(ABS((H20-G20)/G20),"0.0%"))),"")) -> ▼ -4.3% | I21: =IF(H20="","",IFERROR(IF(I20=H20,"—",IF(I20>H20,"▲ +"&TEXT((I20-H20)/H20,"0.0%"),"▼ -"&TEXT(ABS((I20-H20)/H20),"0.0%"))),"")) -> ▲ +9.6% | J21: =IF(I20="","",IFERROR(IF(J20=I20,"—",IF(J20>I20,"▲ +"&TEXT((J20-I20)/I20,"0.0%"),"▼ -"&TEXT(ABS((J20-I20)/I20),"0.0%"))),"")) -> ▼ -15.5% | K21: =IF(J20="","",IFERROR(IF(K20=J20,"—",IF(K20>J20,"▲ +"&TEXT((K20-J20)/J20,"0.0%"),"▼ -"&TEXT(ABS((K20-J20)/J20),"0.0%"))),"")) -> ▼ -0.1% | ... M21: =IF(L20="","",IFERROR(IF(M20=L20,"—",IF(M20>L20,"▲ +"&TEXT((M20-L20)/L20,"0.0%"),"▼ -"&TEXT(ABS((M20-L20)/L20),"0.0%"))),"")) -> ▲ +5.7%

Sheet Settings
A1: SYSTEM SETTINGS & CONFIGURATION
A3: INSTRUCTIONS FOR USE
A4: 1. Add new months using the menu: Monthly Reports > Add New Month
A5: 2. Update data in the current month sheets (Banks, Advances, Suspense, Outstanding)
A6: 3. View comparison reports and dashboard to track trends
A7: 4. Edit the master lists below to customize dropdowns in all sheets
A8: 5. Use "Fix Dropdowns" menu item after editing lists to update all sheets
A12: MASTER LISTS
A14: BANKS | C14: SALESMEN | E14: AREAS
A15: Alrajhi-1097 | C15: nidheesh | E15: Al Ahsa Wholesale
A16: Alrajhi-new | C16: jaseel | E16: Riyadh
A17: SNB Al Ahsa Branch | C17: bassam | E17: Dammam wholesale
A18: Albilad USD | C18: akmal | E18: Company Direct Sales
C19: arshad | E19: Dammam Retail
C20: Shameer riyadh | E20: Al Ahsa-2
C21: company sales | E21: Al Ahsa-3
C22: shafi | E22: Al Ahsa-1
C23: ashik | E23: Hafar Al Batin
C24: dhiya | E24: Qaseem
C25: khalid | E25: Dammam Retail-2
C26: shabeer
C27: al ahsa-4
C28: samir dmm
C29: shareef
C30: samir
A31: Version:
A32: SYSTEM INFORMATION
A33: SYSTEM INFORMATION
A34: Version:
A35: Last Updated: | B35: 45895.652 | D35: SUSPENSE Base (Jan) | E35: -17267.64
A36: Created By: | B36: 45896.128 | D36: SUSPENSE Base (Jan) | E36: -17267.64
A37: Created By: | B37: Account Department
D38: ADVANCES Base (Jan) | E38: 163800.84

Sheet Banks_NOV-2025
A1: BANK SUMMARY - NOV-2025
A3: Bank Name | B3: Opening Balance | C3: Total Received | D3: Bank Charges | E3: Total Payments | F3: Closing Balance | G3: Notes
A4: Alrajhi-1097 | B4: 210693.67 | F4: =B4+C4-D4-E4 -> 210693.67
A5: Alrajhi-new | B5: 564500.97 | F5: =B5+C5-D5-E5 -> 564500.97
A6: SNB Al Ahsa Branch | B6: 1562570.6 | F6: =B6+C6-D6-E6 -> 1562570.6
A7: Albilad | B7: 160054.48 | F7: =B7+C7-D7-E7 -> 160054.48
A9: SUB-TOTAL SAR | B9: =SUM(B4:B7) -> 2497819.7 | C9: =SUM(C4:C7) -> 0 | D9: =SUM(D4:D7) -> 0 | E9: =SUM(E4:E7) -> 0 | F9: =SUM(F4:F7) -> 2497819.7
A11: USD ACCOUNTS
A12: Bank Name | B12: Opening | C12: Amount Received | D12: Bank Charge | E12: Payment | F12: Balance | G12: Notes
A13: Albilad USD | B13: 133.57 | F13: =B13+C13-D13-E13 -> 133.57
A15: SUB-TOTAL USD | B15: =SUM(B13) -> 133.57 | C15: =SUM(C13) -> 0 | D15: =SUM(D13) -> 0 | E15: =SUM(E13) -> 0 | F15: =SUM(F13) -> 133.57
A17: GRAND TOTAL (SAR + USD Converted) | B17: =B9+B15*3.75 -> 2498320.6 | C17: =C9+C15*3.75 -> 0 | D17: =D9+D15*3.75 -> 0 | E17: =E9+E15*3.75 -> 0 | F17: =F9+F15*3.75 -> 2498320.6
A19: SUMMARY
A20: Total Bank Balance (SAR): | C20: =F17 -> 2498320.6

Sheet Advances_NOV-2025
A1: ADVANCE RECONCILIATION - NOV-2025
A3: OPENING BALANCE | B3: 540959.39 | D3: CLOSING BALANCE | E3: =0+SUM(E7:E1000) -> #REF!
A5: TRANSACTIONS
A6: Date | B6: Voucher No | C6: Description | D6: Person/Party | E6: Advance Given | F6: Amount Settled | G6: Running Balance
G7: =IF(E7="","",B3+E7-F7)
G8: =IF(E8="","",G7+E8-F8)
G9: =IF(E9="","",G8+E9-F9)
G10: =IF(E10="","",G9+E10-F10)
G11: =IF(E11="","",G10+E11-F11)
G12: =IF(E12="","",G11+E12-F12)
G13: =IF(E13="","",G12+E13-F13)
G14: =IF(E14="","",G13+E14-F14)
G15: =IF(E15="","",G14+E15-F15)
G16: =IF(E16="","",G15+E16-F16)
G17: =IF(E17="","",G16+E17-F17)
G18: =IF(E18="","",G17+E18-F18)
G19: =IF(E19="","",G18+E19-F19)
... G100: =IF(E100="","",G99+E100-F100)
A102: TOTAL | E102: =SUM(E7:E1000) -> #REF! | F102: =SUM(F7:F1000) -> #REF!

Sheet Suspense_NOV-2025
A1: SUSPENSE RECONCILIATION - NOV-2025
A3: OPENING BALANCE | B3: -186506.88 | D3: CLOSING BALANCE | E3: =0+SUM(E7:E1000)-SUM(F7:F1000) -> #REF!
A5: UNIDENTIFIED TRANSACTIONS
A6: Date | B6: Journal No | C6: Description | D6: Reference | E6: Debit | F6: Credit | G6: Running Balance
G7: =IF(AND(E7="",F7=""),"",B3+E7-F7)
G8: =IF(AND(E8="",F8=""),"",G7+E8-F8)
G9: =IF(AND(E9="",F9=""),"",G8+E9-F9)
G10: =IF(AND(E10="",F10=""),"",G9+E10-F10)
G11: =IF(AND(E11="",F11=""),"",G10+E11-F11)
G12: =IF(AND(E12="",F12=""),"",G11+E12-F12)
G13: =IF(AND(E13="",F13=""),"",G12+E13-F13)
G14: =IF(AND(E14="",F14=""),"",G13+E14-F14)
G15: =IF(AND(E15="",F15=""),"",G14+E15-F15)
G16: =IF(AND(E16="",F16=""),"",G15+E16-F16)
G17: =IF(AND(E17="",F17=""),"",G16+E17-F17)
G18: =IF(AND(E18="",F18=""),"",G17+E18-F18)
G19: =IF(AND(E19="",F19=""),"",G18+E19-F19)
... G100: =IF(AND(E100="",F100=""),"",G99+E100-F100)
A102: TOTAL | E102: =SUM(E7:E1000) -> #REF! | F102: =SUM(F7:F1000) -> #REF!

Sheet Outstanding_NOV-2025
A1: CUSTOMER OUTSTANDING - NOV-2025
A3: Salesman | B3: Total Outstanding | C3: No. of Customers | D3: Average
A4: nidheesh | B4: =SUMIF($D$23:$D$502,A4,$G$23:$G$502) -> 79345.24 | C4: =COUNTIF($D$23:$D$502,A4) -> 54 | D4: =IFERROR(B4/C4,0) -> 1469.3563
A5: jaseel | B5: =SUMIF($D$23:$D$502,A5,$G$23:$G$502) -> 19951.36 | C5: =COUNTIF($D$23:$D$502,A5) -> 17 | D5: =IFERROR(B5/C5,0) -> 1173.6094
A6: bassam | B6: =SUMIF($D$23:$D$502,A6,$G$23:$G$502) -> 22733.87 | C6: =COUNTIF($D$23:$D$502,A6) -> 15 | D6: =IFERROR(B6/C6,0) -> 1515.5913
A7: akmal | B7: =SUMIF($D$23:$D$502,A7,$G$23:$G$502) -> 34121.05 | C7: =COUNTIF($D$23:$D$502,A7) -> 14 | D7: =IFERROR(B7/C7,0) -> 2437.2179
A8: arshad | B8: =SUMIF($D$23:$D$502,A8,$G$23:$G$502) -> 486637.4 | C8: =COUNTIF($D$23:$D$502,A8) -> 26 | D8: =IFERROR(B8/C8,0) -> 18716.823
A9: Shameer riyadh | B9: =SUMIF($D$23:$D$502,A9,$G$23:$G$502) -> 92907.92 | C9: =COUNTIF($D$23:$D$502,A9) -> 61 | D9: =IFERROR(B9/C9,0) -> 1523.0807
A10: company sales | B10: =SUMIF($D$23:$D$502,A10,$G$23:$G$502) -> 976412.87 | C10: =COUNTIF($D$23:$D$502,A10) -> 15 | D10: =IFERROR(B10/C10,0) -> 65094.191
A11: shafi | B11: =SUMIF($D$23:$D$502,A11,$G$23:$G$502) -> 18398.82 | C11: =COUNTIF($D$23:$D$502,A11) -> 35 | D11: =IFERROR(B11/C11,0) -> 525.68057
A12: ashik | B12: =SUMIF($D$23:$D$502,A12,$G$23:$G$502) -> 17807.28 | C12: =COUNTIF($D$23:$D$502,A12) -> 26 | D12: =IFERROR(B12/C12,0) -> 684.89538
A13: dhiya | B13: =SUMIF($D$23:$D$502,A13,$G$23:$G$502) -> 270754.61 | C13: =COUNTIF($D$23:$D$502,A13) -> 21 | D13: =IFERROR(B13/C13,0) -> 12893.077
A14: khalid | B14: =SUMIF($D$23:$D$502,A14,$G$23:$G$502) -> 89837.02 | C14: =COUNTIF($D$23:$D$502,A14) -> 112 | D14: =IFERROR(B14/C14,0) -> 802.11625
A15: shabeer | B15: =SUMIF($D$23:$D$502,A15,$G$23:$G$502) -> 0 | C15: =COUNTIF($D$23:$D$502,A15) -> 0 | D15: =IFERROR(B15/C15,0) -> 0
... A18: shareef | B18: =SUMIF($D$23:$D$502,A18,$G$23:$G$502) -> 4257.5 | C18: =COUNTIF($D$23:$D$502,A18) -> 17 | D18: =IFERROR(B18/C18,0) -> 250.44118
A19: samir | B19: =SUMIF($D$23:$D$502,A19,$G$23:$G$502) -> 15016.49 | C19: =COUNTIF($D$23:$D$502,A19) -> 9 | D19: =IFERROR(B23/C19,0) -> 0
A20: TOTAL | B20: =SUM(B4:B19) -> 2179683.5 | C20: =SUM(C4:C19) -> 441 | D20: =IFERROR(B23/C20,0) -> 0
A22: Customer Code | B22: Customer Name | C22: Area | D22: Salesman | E22: Invoice Amount | F22: Paid Amount | G22: Balance | H22: Days
A23: CUST63 | B23: Saudi marketting | C23: Al Ahsa-1 | D23: jaseel | E23: 1019.82 | G23: =IF(E23="","",E23-F23) -> 1019.82
A24: CUST84 | B24: Najmath AL khayrath | C24: Al Ahsa-1 | D24: jaseel | E24: 1939.7 | G24: =IF(E24="","",E24-F24) -> 1939.7
A25: CUST163 | B25: Al sahla oasis groceri for foodstuff | C25: Al Ahsa-1 | D25: jaseel | E25: 192.96 | G25: =IF(E25="","",E25-F25) -> 192.96
A26: CUST204 | B26: Thamveenath Noorul usam | C26: Al Ahsa-1 | D26: jaseel | E26: 1460.78 | G26: =IF(E26="","",E26-F26) -> 1460.78
A27: CUST561 | B27: Grocery naster | C27: Al Ahsa-1 | D27: jaseel | E27: 284.96 | G27: =IF(E27="","",E27-F27) -> 284.96
A28: CUST1482 | B28: Wahab Al khaleej 2 | C28: Al Ahsa-1 | D28: jaseel | E28: 917.88 | G28: =IF(E28="","",E28-F28) -> 917.88
A29: CUST1999 | B29: Zone mart (j) | C29: Al Ahsa-1 | D29: jaseel | E29: 1201.86 | G29: =IF(E29="","",E29-F29) -> 1201.86
A30: CUST2141 | B30: Al Qafila al khalijiyyah supermarket | C30: Al Ahsa-1 | D30: jaseel | E30: 1257.81 | G30: =IF(E30="","",E30-F30) -> 1257.81
A31: CUST2237 | B31: Ghaith al safat food supplies | C31: Al Ahsa-1 | D31: jaseel | E31: 2567.63 | G31: =IF(E31="","",E31-F31) -> 2567.63
A32: CUST2326 | B32: Al Zahra (umm | C32: Al Ahsa-1 | D32: jaseel | E32: 1584.79 | G32: =IF(E32="","",E32-F32) -> 1584.79
A33: CUST2446 | B33: Durrat alshakhs foodstuff supplies | C33: Al Ahsa-1 | D33: jaseel | E33: 600 | G33: =IF(E33="","",E33-F33) -> 600
A34: CUST2493 | B34: Kayf al alha market | C34: Al Ahsa-1 | D34: jaseel | E34: 2569.55 | G34: =IF(E34="","",E34-F34) -> 2569.55
... A463: CUST6225 | B463: Amazon saudi Trading CO (al Azeeziya) | C463: Hafar Al Batin | D463: samir dmm | E463: 8503.9 | G463: =IF(E463="","",E463-F463) -> 8503.9
G464: =IF(E464="","",E464-F464)
G465: =IF(E465="","",E465-F465)
G466: =IF(E466="","",E466-F466)
G467: =IF(E467="","",E467-F467)
G468: =IF(E468="","",E468-F468)
G469: =IF(E469="","",E469-F469)
G470: =IF(E470="","",E470-F470)
G471: =IF(E471="","",E471-F471)
G472: =IF(E472="","",E472-F472)
...

Sheet Banks_SEP-2025
A1: BANK SUMMARY - SEP-2025
A3: Bank Name | B3: Opening Balance | C3: Total Received | D3: Bank Charges | E3: Total Payments | F3: Closing Balance | G3: Notes
A4: Alrajhi-1097 | B4: 730511.72 | C4: 534244.8 | D4: 3574.6 | E4: 50288.93 | F4: =B4+C4-D4-E4 -> 1210893
A5: Alrajhi-new | B5: 613561.62 | C5: 415787.99 | D5: 0 | E5: 0 | F5: =B5+C5-D5-E5 -> 1029349.6
A6: SNB Al Ahsa Branch | B6: 770824.04 | C6: 474609.66 | D6: 345 | E6: 0 | F6: =B6+C6-D6-E6 -> 1245088.7
A7: Albilad | B7: 333879.5 | C7: 806860 | D7: 126.5 | E7: 787076.93 | F7: =B7+C7-D7-E7 -> 353536.07
A9: SUB-TOTAL SAR | B9: =SUM(B4:B7) -> 2448776.9 | C9: =SUM(C4:C7) -> 2231502.5 | D9: =SUM(D4:D7) -> 4046.1 | E9: =SUM(E4:E7) -> 837365.86 | F9: =SUM(F4:F7) -> 3838867.4
A11: USD ACCOUNTS
A12: Bank Name | B12: Opening | C12: Amount Received | D12: Bank Charge | E12: Payment | F12: Balance | G12: Notes
A13: Albilad USD | B13: 423.48 | C13: 13303.18 | E13: 10674.33 | F13: =B13+C13-D13-E13 -> 3052.33
A15: SUB-TOTAL USD | B15: =SUM(B13) -> 423.48 | C15: =SUM(C13) -> 13303.18 | D15: =SUM(D13) -> 0 | E15: =SUM(E13) -> 10674.33 | F15: =SUM(F13) -> 3052.33
A17: GRAND TOTAL (SAR + USD Converted) | B17: =B9+B15*3.75 -> 2450364.9 | C17: =C9+C15*3.75 -> 2281389.4 | D17: =D9+D15*3.75 -> 4046.1 | E17: =E9+E15*3.75 -> 877394.6 | F17: =F9+F15*3.75 -> 3850313.6
A19: SUMMARY
A20: Total Bank Balance (SAR): | C20: =F17 -> 3850313.6

Sheet Banks_OCT-2025
A1: BANK SUMMARY - OCT-2025
A3: Bank Name | B3: Opening Balance | C3: Total Received | D3: Bank Charges | E3: Total Payments | F3: Closing Balance | G3: Notes
A4: Alrajhi-1097 | B4: 1210893 | C4: 703586.3 | D4: 3838.82 | E4: 1699946.8 | F4: =B4+C4-D4-E4 -> 210693.67
A5: Alrajhi-new | B5: 1029349.6 | C5: 538084.41 | D5: 8.05 | E5: 1002925 | F5: =B5+C5-D5-E5 -> 564500.97
A6: SNB Al Ahsa Branch | B6: 1245088.7 | C6: 717855.66 | D6: 373.75 | E6: 400000 | F6: =B6+C6-D6-E6 -> 1562570.6
A7: Albilad | B7: 353536.07 | C7: 2429125 | D7: 109.25 | E7: 2622497.3 | F7: =B7+C7-D7-E7 -> 160054.48
A9: SUB-TOTAL SAR | B9: =SUM(B4:B7) -> 3838867.4 | C9: =SUM(C4:C7) -> 4388651.4 | D9: =SUM(D4:D7) -> 4329.87 | E9: =SUM(E4:E7) -> 5725369.1 | F9: =SUM(F4:F7) -> 2497819.7
A11: USD ACCOUNTS
A12: Bank Name | B12: Opening | C12: Amount Received | D12: Bank Charge | E12: Payment | F12: Balance | G12: Notes
A13: Albilad USD | B13: 3052.33 | C13: 530794.71 | D13: 107.31 | E13: 533606.16 | F13: =B13+C13-D13-E13 -> 133.57
A15: SUB-TOTAL USD | B15: =SUM(B13) -> 3052.33 | C15: =SUM(C13) -> 530794.71 | D15: =SUM(D13) -> 107.31 | E15: =SUM(E13) -> 533606.16 | F15: =SUM(F13) -> 133.57
A17: GRAND TOTAL (SAR + USD Converted) | B17: =B9+B15*3.75 -> 3850313.6 | C17: =C9+C15*3.75 -> 6379131.5 | D17: =D9+D15*3.75 -> 4732.2825 | E17: =E9+E15*3.75 -> 7726392.2 | F17: =F9+F15*3.75 -> 2498320.6
A19: SUMMARY
A20: Total Bank Balance (SAR): | C20: =F17 -> 2498320.6

Sheet Advances_OCT-2025
A1: ADVANCE RECONCILIATION - OCT-2025
A3: OPENING BALANCE | B3: 504511.39 | D3: CLOSING BALANCE | E3: =163800.84+SUM(E7:E101) -> 540959.39
A5: TRANSACTIONS
A6: Date | B6: Voucher No | C6: Description | D6: Person/Party | E6: Advance Given | F6: Amount Settled | G6: Running Balance
A7: 17/04/2024 | B7: EXP3391 | C7: Shirfan - Cash withdraw -- | E7: 1500 | G7: =IF(E7="","",B3+E7-F7) -> 506011.39
A8: 27/05/2024 | B8: EXP3462 | C8: THOYYIB VEHICLE WINGE EXP- | E8: 350 | G8: =IF(E8="","",G7+E8-F8) -> 506361.39
A9: 27/05/2024 | B9: EXP3462 | C9: ADVANCES -THOYYIBE VEHICLE COMPLAINT- | E9: 143.48 | G9: =IF(E9="","",G8+E9-F9) -> 506504.87
A10: 27/05/2024 | B10: EXP3462 | C10: ADVANCES -THOYYIBE VEHICLE COMPLAINT- | E10: 600 | G10: =IF(E10="","",G9+E10-F10) -> 507104.87
A11: 16/06/2024 | B11: JN5365 | C11: COLLECTION CASH TAKEN BY HANI | E11: 34000 | G11: =IF(E11="","",G10+E11-F11) -> 541104.87
A12: 24/06/2024 | B12: EXP3614 | C12: ADVANCE-SALMANUL FARIZ-RIYADH- | E12: 500 | G12: =IF(E12="","",G11+E12-F12) -> 541604.87
A13: 45298 | B13: EXP3645 | C13: ASHIK-ADVANCE- | E13: 4000 | G13: =IF(E13="","",G12+E13-F13) -> 545604.87
A14: 45450 | B14: EXP3699 | C14: FT24188664289852 Ben WHITE GRAPHICS-ADVANCE FOR RECEPTION WORK- | E14: 2790 | G14: =IF(E14="","",G13+E14-F14) -> 548394.87
A15: 13/08/2024 | B15: EXP4197 | C15: AL JARAHA ADVANCE PAYMENT-METAL DETECTOR AND HIGHSPEED PACKING MACHINE-FT24226303374754- | E15: 74656.7 | G15: =IF(E15="","",G14+E15-F15) -> 623051.57
A16: 13/08/2024 | B16: EXP4198 | C16: AL JARAHA ADVANCE PAYMENT-METAL DETECTOR AND HIGHSPEED PACKING MACHINE-FT24226094147820- | E16: 25655.23 | G16: =IF(E16="","",G15+E16-F16) -> 648706.8
A17: 27/08/2024 | B17: EXP4327 | C17: FT24240219059921 Ben EGYPTIAN SAUDI IMPORT EXPORT PAPER-DOUBLE TRANSFER-AMOUNT- | E17: 5000 | G17: =IF(E17="","",G16+E17-F17) -> 653706.8
A18: 13/10/2024 | B18: EXP4386 | C18: SHIRFAN ADVANCE FROM NIDHEESH COLLECTION- | E18: 4650 | G18: =IF(E18="","",G17+E18-F18) -> 658356.8
A19: 20/10/2024 | B19: EXP4423 | C19: THOYYIB ADVANCE QASEEM NEW ROUTE- | E19: 500 | G19: =IF(E19="","",G18+E19-F19) -> 658856.8
A20: 31/10/2024 | C20: MANAFIZ RENT DMM ROUTE | E20: 16857.45 | G20: =IF(E20="","",G19+E20-F20) -> 675714.25
A21: 45546 | B21: EXP4569 | C21: SALMAN FARIZ ADVANCE FROM NIDHEESH COLLECTION- | E21: 4450 | G21: =IF(E21="","",G20+E21-F21) -> 680164.25
A22: 45637 | B22: EXP4573 | C22: ASLAM ADVANCE TO SALMAN FARIZ- | E22: 80 | G22: =IF(E22="","",G21+E22-F22) -> 680244.25
A23: 45577 | B23: EXP4697 | C23: AL JARAHA ADVANCE PAYMENT-METAL DETECTOR AND HIGHSPEED PACKING MACHINE-FT24226094147820- | E23: 49001.48 | G23: =IF(E23="","",G22+E23-F23) -> 729245.73
A24: 25/12/2024 | B24: EXP4747 | C24: SHIRFAN ADVANCE NIDHEESH COLLECTION- | E24: 300 | G24: =IF(E24="","",G23+E24-F24) -> 729545.73
A25: 30/12/2024 | B25: EXP4756 | C25: FUEL-ADVANCE-FAWAS- | E25: 150 | G25: =IF(E25="","",G24+E25-F25) -> 729695.73
A26: 14/01/2025 | B26: EXP4790 | C26: Al jara machinary payment- | E26: 51310.45 | G26: =IF(E26="","",G25+E26-F26) -> 781006.18
A27: 45749 | B27: EXP4884 | C27: PURCHASE ADVANCE-ASHOK- | E27: 200 | G27: =IF(E27="","",G26+E27-F27) -> 781206.18
A28: 16/02/2025 | B28: EXP4912 | C28: NNA REPAIR EXP-ASLAM- | E28: 334.8 | G28: =IF(E28="","",G27+E28-F28) -> 781540.98
A29: 16/02/2025 | B29: EXP4912 | C29: NNA REPAIR EXP-AKMAL- | E29: 300 | G29: =IF(E29="","",G28+E29-F29) -> 781840.98
A30: 16/02/2025 | B30: EXP4912 | C30: NNA REPAIR EXP-ASLAM- | E30: 350 | G30: =IF(E30="","",G29+E30-F30) -> 782190.98
A31: 45752 | B31: EXP5155 | C31: PURCHASE ADVANCE-ASLAM- | E31: 200 | G31: =IF(E31="","",G30+E31-F31) -> 782390.98
A32: 24/05/2025 | B32: EXP5247 | C32: SHIRFAN ADVANCES- | E32: 170 | G32: =IF(E32="","",G31+E32-F32) -> 782560.98
A33: 31/05/2025 | C33: VEHICLE SERVICE BALANCE-SHIRFAN SIR | E33: 219 | G33: =IF(E33="","",G32+E33-F33) -> 782779.98
A34: 45997 | B34: EXP5275 | C34: ADVANCE-SALMAN SIR- | E34: 260.96 | G34: =IF(E34="","",G33+E34-F34) -> 783040.94
A35: 26/06/2025 | B35: EXP5389 | C35: BAYCITY BALANCE-AMOUNT PAID-20000 SETTLED-11000 - | E35: 9000 | G35: =IF(E35="","",G34+E35-F35) -> 792040.94
A36: 29/06/2025 | B36: EXP5402 | C36: SALARY ADVANCE-ASLAM- | E36: 100 | G36: =IF(E36="","",G35+E36-F36) -> 792140.94
A37: 21/07/2025 | B37: EXP5475 | C37: SHIRFAN SIR ADVANCE- | E37: 200 | G37: =IF(E37="","",G36+E37-F37) -> 792340.94
A38: 19/08/2025 | B38: EXP5590 | C38: SUSHI ADVANCE -LABOUR CHARGE-09-08-2025 TO 14-08-2025-TOTAL AMOUNT-7500/-- | E38: 1500 | G38: =IF(E38="","",G37+E38-F38) -> 793840.94
A39: 19/08/2025 | B39: EXP5590 | C39: SALMAN SIR ADVANCE FOR TRAFFIC VIOLATION- | E39: 450 | G39: =IF(E39="","",G38+E39-F39) -> 794290.94
A40: 21/08/2025 | B40: EXP5603 | C40: SALMAN SIR ADVANCE-NIDHEESH- | E40: 100 | G40: =IF(E40="","",G39+E40-F40) -> 794390.94
A41: 45939 | B41: EXP5681 | C41: VEHICLE KEY DUPLICATE- | E41: 15 | G41: =IF(E41="","",G40+E41-F41) -> 794405.94
A42: 13/09/2025 | B42: EXP5683 | C42: KOYA ADVANCE FROM DHIYA CLLECTION NNA FUEL- | E42: 100 | G42: =IF(E42="","",G41+E42-F42) -> 794505.94
...

Sheet Suspense_OCT-2025
A1: SUSPENSE RECONCILIATION - OCT-2025
A3: OPENING BALANCE | B3: -59758.42 | D3: CLOSING BALANCE | E3: =-17267.64+SUM(E7:E1000)-SUM(F7:F1000) -> -186506.88
A5: UNIDENTIFIED TRANSACTIONS
A6: Date | B6: Journal No | C6: Description | D6: Reference | E6: Debit | F6: Credit | G6: Running Balance
A7: 45295 | B7: JN4377 | C7: Bank sale - Thoyyib - DMM | E7: 24078
A8: 45295 | B8: JN4381 | C8: BANK SALES ON POS -NIDHEESH | E8: 142.97
A9: 45326 | B9: JN4384 | C9: BANK SALE POS FASIL | E9: 159.97
A10: 45326 | B10: JN4384 | C10: BANK SALE POS FASIL | E10: 503.93
A11: 45326 | B11: JN4384 | C11: BANK SALE POS FASIL | E11: 476.93
A12: 14/04/2024 | B12: JN4467 | C12: Bank sale - POS - Jaseel | E12: 564.94
A13: 45355 | B13: JN4425 | C13: CHEQUE DEPOSIT -SAMIR | E13: 0 | F13: 4450.57
A14: 22/04/2024 | B14: EXP4515 | C14: for bank reconciliation-FT24113842248106 Ben Saalim Alhamid -NOT RECIEVED IN BILL- | E14: 4348.76 | F14: 0
A15: 26/06/2024 | B15: JN7242 | C15: BAB#38825126#2792024062411513800001211042 -SADAD REFUND | E15: 0 | F15: 100
A16: 13/08/2024 | B16: JN6115 | C16: MISTAKE ENTRY BALANCE AMOUNT NOT IDENTIFIED BILL-SHABEER CASH BOOK | E16: 365.68
A17: 23/11/2024 | B17: JN7638 | C17: BANK TRANSFER-NOT IDENTIFIED | E17: 0 | F17: 2175.71
A18: 14/12/2024 | B18: JN7950 | C18: BANK POSNO-8117929503058544 | E18: 0 | F18: 1.94
A19: 14/01/2025 | B19: JN8176 | C19: BANK TRANSFER-NIDHEEESH | E19: 0 | F19: 1
A20: 19/01/2025 | B20: JN8400 | C20: BANK TRANSFER- | E20: 0 | F20: 2550
A21: 45690 | B21: JN8696 | C21: BANK TRANSFER-NOT IDENTIFIED | E21: 0 | F21: 2500
A22: 45750 | B22: JN9046 | C22: BANK TRANSFER-NOT IDENTIFIED | E22: 0 | F22: 2000
A23: 13/03/2025 | C23: BANK TRANSFER-SHAREEF | E23: 201 | F23: 0
A24: 45873 | B24: JN9444 | C24: BANK TRANSFER-NOT IDENTIFIED | E24: 0 | F24: 1500
A25: 45965 | B25: JN9447 | C25: BANK-POS | E25: 0 | F25: 0.02
A26: 20/04/2025 | B26: JN9451 | C26: BANK TRANSFER-NOT IDENTIFIED | E26: 0 | F26: 285.96
A27: 20/04/2025 | B27: JN9452 | C27: BANK TRANSFER-NOT IDENTIFIED | E27: 0 | F27: 1380
A28: 29/04/2025 | B28: JN9455 | C28: BANK TRANSFER-NOT IDENTIFIED | E28: 0 | F28: 1000
A29: 45301 | B29: JN9330 | C29: UNKNOWN CREDIT-BILAD -OCTOBER | F29: 4000
A30: 45721 | B30: JN9446 | C30: BANK POS | E30: 0 | F30: 0.01
A31: 45782 | B31: JN9739 | C31: BANK TRANSFER- | E31: 0 | F31: 1600
A32: 45996 | B32: JN9748 | C32: BANK TRANSFER- | E32: 0 | F32: 1000
A33: 17/05/2025 | B33: JN9793 | C33: BANK TRANSFER- | E33: 0 | F33: 1389
A34: 18/05/2025 | B34: JN9787 | C34: BANK POS-SHAREEF | E34: 0 | F34: 523.92
A35: 23/05/2025 | B35: JN9795 | C35: BANK TRANSFER- | E35: 0 | F35: 1000
A36: 27/05/2025 | B36: JN9831 | C36: BANK TRANSFER- | E36: 0 | F36: 1488
A37: 45783 | B37: JN10142 | C37: BANK TRANSFER-NOT IDENTIFIED | E37: 0 | F37: 1005.88
A38: 45906 | B38: JN10143 | C38: BANK POS-SHAREEF | E38: 0 | F38: 108.98
A39: 19/06/2025 | B39: JN10145 | C39: BANK TRANSFER-NOT IDENTIFIED | E39: 0 | F39: 1020.84
A40: 21/06/2025 | B40: JN10146 | C40: BANK | E40: 0 | F40: 0.01
A41: 26/06/2025 | B41: JN10147 | C41: BANK TRANSFER-NOT IDENTIFIED | E41: 0 | F41: 290
A42: 30/06/2025 | C42: BANK CHARGES | E42: 0 | F42: 29
...

Sheet Outstanding_OCT-2025
A1: CUSTOMER OUTSTANDING - OCT-2025
A3: Salesman | B3: Total Outstanding | C3: No. of Customers | D3: Average
A4: Nidheesh | B4: =SUMIF($D$19:$D$502,A4,$G$19:$G$502) -> 76836.77 | C4: =COUNTIF($D$19:$D$502,A4) -> 47 | D4: =IFERROR(B4/C4,0) -> 1634.8249
A5: Jaseel | B5: =SUMIF($D$19:$D$502,A5,$G$19:$G$502) -> 20506.08 | C5: =COUNTIF($D$19:$D$502,A5) -> 18 | D5: =IFERROR(B5/C5,0) -> 1139.2267
A6: Bassam | B6: =SUMIF($D$19:$D$502,A6,$G$19:$G$502) -> 25219.28 | C6: =COUNTIF($D$19:$D$502,A6) -> 33 | D6: =IFERROR(B6/C6,0) -> 764.22061
A7: akmal | B7: =SUMIF($D$19:$D$502,A7,$G$19:$G$502) -> 45795.01 | C7: =COUNTIF($D$19:$D$502,A7) -> 19 | D7: =IFERROR(B7/C7,0) -> 2410.2637
A8: arshad | B8: =SUMIF($D$19:$D$502,A8,$G$19:$G$502) -> 366543.83 | C8: =COUNTIF($D$19:$D$502,A8) -> 26 | D8: =IFERROR(B8/C8,0) -> 14097.84
A9: Shameer riyadh | B9: =SUMIF($D$19:$D$502,A9,$G$19:$G$502) -> 72659.84 | C9: =COUNTIF($D$19:$D$502,A9) -> 55 | D9: =IFERROR(B9/C9,0) -> 1321.088
A10: company sales | B10: =SUMIF($D$19:$D$502,A10,$G$19:$G$502) -> 1056569.4 | C10: =COUNTIF($D$19:$D$502,A10) -> 15 | D10: =IFERROR(B10/C10,0) -> 70437.962
A11: shafi | B11: =SUMIF($D$19:$D$502,A11,$G$19:$G$502) -> 17259.59 | C11: =COUNTIF($D$19:$D$502,A11) -> 35 | D11: =IFERROR(B11/C11,0) -> 493.13114
A12: ashik | B12: =SUMIF($D$19:$D$502,A12,$G$19:$G$502) -> 27926.05 | C12: =COUNTIF($D$19:$D$502,A12) -> 28 | D12: =IFERROR(B12/C12,0) -> 997.35893
A13: dhiya | B13: =SUMIF($D$19:$D$502,A13,$G$19:$G$502) -> 245613.5 | C13: =COUNTIF($D$19:$D$502,A13) -> 19 | D13: =IFERROR(B13/C13,0) -> 12927.026
A14: salman | B14: =SUMIF($D$19:$D$502,A14,$G$19:$G$502) -> 0 | C14: =COUNTIF($D$19:$D$502,A14) -> 0 | D14: =IFERROR(B14/C14,0) -> 0
A15: samir | B15: =SUMIF($D$19:$D$502,A15,$G$19:$G$502) -> 9086.56 | C15: =COUNTIF($D$19:$D$502,A15) -> 10 | D15: =IFERROR(B15/C15,0) -> 908.656
A16: TOTAL | B16: =SUM(B4:B15) -> 1964015.9 | C16: =SUM(C4:C15) -> 305 | D16: =IFERROR(B16/C16,0) -> 6439.3965
A18: Customer Code | B18: Customer Name | C18: Area | D18: Salesman | E18: Invoice Amount | F18: Paid Amount | G18: Balance | H18: Days
A19: CUST63 | B19: Saudi marketting | C19: Al Ahsa-1 | D19: Jaseel | E19: 1019.82 | G19: =IF(E19="","",E19-F19) -> 1019.82
A20: CUST84 | B20: Najmath AL khayrath | C20: Al Ahsa-1 | D20: Jaseel | E20: 1939.7 | G20: =IF(E20="","",E20-F20) -> 1939.7
A21: CUST204 | B21: Thamveenath Noorul usam | C21: Al Ahsa-1 | D21: Jaseel | E21: 1460.78 | G21: =IF(E21="","",E21-F21) -> 1460.78
A22: CUST437 | B22: Aswaq sahab alhadid | C22: Al Ahsa-1 | D22: Jaseel | E22: 1049.85 | G22: =IF(E22="","",E22-F22) -> 1049.85
A23: CUST561 | B23: Grocery naster | C23: Al Ahsa-1 | D23: Jaseel | E23: 284.96 | G23: =IF(E23="","",E23-F23) -> 284.96
A24: CUST565 | B24: Sahab mart | C24: Al Ahsa-1 | D24: Jaseel | E24: 1087.86 | G24: =IF(E24="","",E24-F24) -> 1087.86
A25: CUST1967 | B25: Thanveenath hoor sahadath | C25: Al Ahsa-1 | D25: Jaseel | E25: 158.97 | G25: =IF(E25="","",E25-F25) -> 158.97
A26: CUST1999 | B26: Zone mart (j) | C26: Al Ahsa-1 | D26: Jaseel | E26: 1507.81 | G26: =IF(E26="","",E26-F26) -> 1507.81
A27: CUST2139 | B27: Sama alsaada foodstuff markets | C27: Al Ahsa-1 | D27: Jaseel | E27: 600 | G27: =IF(E27="","",E27-F27) -> 600
A28: CUST2141 | B28: Al Qafila al khalijiyyah supermarket | C28: Al Ahsa-1 | D28: Jaseel | E28: 1257.81 | G28: =IF(E28="","",E28-F28) -> 1257.81
A29: CUST2237 | B29: Ghaith al safat food supplies | C29: Al Ahsa-1 | D29: Jaseel | E29: 2567.63 | G29: =IF(E29="","",E29-F29) -> 2567.63
A30: CUST2326 | B30: Al Zahra (umm | C30: Al Ahsa-1 | D30: Jaseel | E30: 1415.82 | G30: =IF(E30="","",E30-F30) -> 1415.82
... A437: CUST6152 | B437: Shareekth kamal al thawfeer al thijariyath dl dammam | C437: Dammam Retail | D437: akmal | E437: 4284.11 | G437: =IF(E437="","",E437-F437) -> 4284.11
G438: =IF(E438="","",E438-F438)
G439: =IF(E439="","",E439-F439)
G440: =IF(E440="","",E440-F440)
G441: =IF(E441="","",E441-F441)
G442: =IF(E442="","",E442-F442)
G443: =IF(E443="","",E443-F443)
G444: =IF(E444="","",E444-F444)
G445: =IF(E445="","",E445-F445)
G446: =IF(E446="","",E446-F446)
G447: =IF(E447="","",E447-F447)
G448: =IF(E448="","",E448-F448)
...

Sheet Advances_SEP-2025
A1: ADVANCE RECONCILIATION - SEP-2025
A3: OPENING BALANCE | B3: 473840.39 | D3: CLOSING BALANCE | E3: =163800.84+SUM(E7:E101) -> 504511.39
A5: TRANSACTIONS
A6: Date | B6: Voucher No | C6: Description | D6: Person/Party | E6: Advance Given | F6: Amount Settled | G6: Running Balance
A7: 17/04/2024 | B7: EXP3391 | C7: Shirfan - Cash withdraw -- | E7: 1500 | G7: =IF(E7="","",B3+E7-F7) -> 475340.39
A8: 27/05/2024 | B8: EXP3462 | C8: THOYYIB VEHICLE WINGE EXP- | E8: 350 | G8: =IF(E8="","",G7+E8-F8) -> 475690.39
A9: 27/05/2024 | B9: EXP3462 | C9: ADVANCES -THOYYIBE VEHICLE COMPLAINT- | E9: 143.48 | G9: =IF(E9="","",G8+E9-F9) -> 475833.87
A10: 27/05/2024 | B10: EXP3462 | C10: ADVANCES -THOYYIBE VEHICLE COMPLAINT- | E10: 600 | G10: =IF(E10="","",G9+E10-F10) -> 476433.87
A11: 16/06/2024 | B11: JN5365 | C11: COLLECTION CASH TAKEN BY HANI | E11: 34000 | G11: =IF(E11="","",G10+E11-F11) -> 510433.87
A12: 24/06/2024 | B12: EXP3614 | C12: ADVANCE-SALMANUL FARIZ-RIYADH- | E12: 500 | G12: =IF(E12="","",G11+E12-F12) -> 510933.87
A13: 45298 | B13: EXP3645 | C13: ASHIK-ADVANCE- | E13: 4000 | G13: =IF(E13="","",G12+E13-F13) -> 514933.87
A14: 45450 | B14: EXP3699 | C14: FT24188664289852 Ben WHITE GRAPHICS-ADVANCE FOR RECEPTION WORK- | E14: 2790 | G14: =IF(E14="","",G13+E14-F14) -> 517723.87
